Workbook

Sheet Datos originales
A1: REVISIÓN CON CÓDIGO rWCVP | H1: RESULTADOS COMBINADOS ÚLTIMA REVISIÓN
A2: Genero.especie | B2: Nombre_aceptado_GBIF | C2: Nombre_aceptado_WCVP | D2: Nombre_aceptado_WFO | E2: Comparacion_tres_fuentes | F2: Detalle_comparacion | G2: Fuente | H2: Nombre_aceptado_GBIF | I2: Nombre_aceptado_WCVP (www.worldfloraonline.org) | J2: Nombre_aceptado_POWO (www.powo.science.kew.org) | K2: Nombre_aceptado_COL (www.catalogueoflife.org) | L2: Nombre_aceptado_WP (www.worldplants.de) | M2: N° de fuentes que coinciden | N2: Especie actual
A3: Abelia.grandiflora | B3: Abelia chinensis | E3: Revisar | F3: Falta resultado en una o más fuentes | G3: World Checklist of Vascular Plants (WCVP), base mantenida por Royal Botanic Gardens, Kew. | H3: =VLOOKUP(A3,Revisión!$A$2:$L$703,6,FALSE) -> Abelia × grandiflora | I3: =VLOOKUP(A3,Revisión!$A$2:$L$703,7,FALSE) -> Abelia × grandiflora | J3: =VLOOKUP(A3,Revisión!$A$2:$L$703,8,FALSE) -> Abelia × grandiflora | K3: =VLOOKUP(A3,Revisión!$A$2:$L$703,9,FALSE) -> - | L3: =VLOOKUP(A3,Revisión!$A$2:$L$703,10,FALSE) -> - | M3: =VLOOKUP(A3,Revisión!$A$2:$L$703,11,FALSE) -> 3 | N3: =IF(E3="Coinciden",D3,IF(E3="Revisar",VLOOKUP(A3,Revisión!$A$2:$L$703,12,FALSE),"")) -> Abelia × grandiflora
A4: Abelia.sp1.M.PL.054 | E4: Revisar | F4: Sin resultados en las tres fuentes | G4: rGbif | H4: =VLOOKUP(A4,Revisión!$A$2:$L$703,6,FALSE) -> #N/A | I4: =VLOOKUP(A4,Revisión!$A$2:$L$703,7,FALSE) -> #N/A | J4: =VLOOKUP(A4,Revisión!$A$2:$L$703,8,FALSE) -> #N/A | K4: =VLOOKUP(A4,Revisión!$A$2:$L$703,9,FALSE) -> #N/A | L4: =VLOOKUP(A4,Revisión!$A$2:$L$703,10,FALSE) -> #N/A | M4: =VLOOKUP(A4,Revisión!$A$2:$L$703,11,FALSE) -> #N/A | N4: =IF(E4="Coinciden",D4,IF(E4="Revisar",VLOOKUP(A4,Revisión!$A$2:$L$703,12,FALSE),"")) -> #N/A
A5: Abelia.serrata | B5: Diabelia serrata | C5: Diabelia serrata | D5: Linnaea serrata | E5: Revisar | F5: Coinciden GBIF y rWCVP; WFO es diferente | G5: taxonomic backbone de World Flora Online (WFO). WFO se desarrolló a partir de The Plant List | H5: =VLOOKUP(A5,Revisión!$A$2:$L$703,6,FALSE) -> Diabelia serrata | I5: =VLOOKUP(A5,Revisión!$A$2:$L$703,7,FALSE) -> Diabelia serrata | J5: =VLOOKUP(A5,Revisión!$A$2:$L$703,8,FALSE) -> Diabelia serrata | K5: =VLOOKUP(A5,Revisión!$A$2:$L$703,9,FALSE) -> - | L5: =VLOOKUP(A5,Revisión!$A$2:$L$703,10,FALSE) -> - | M5: =VLOOKUP(A5,Revisión!$A$2:$L$703,11,FALSE) -> 3 | N5: =IF(E5="Coinciden",D5,IF(E5="Revisar",VLOOKUP(A5,Revisión!$A$2:$L$703,12,FALSE),"")) -> Diabelia serrata
A6: Abelmoschus.manihot | B6: Abelmoschus manihot | C6: Abelmoschus manihot | D6: Abelmoschus manihot | E6: Coinciden | F6: Coinciden las tres fuentes | H6: =VLOOKUP(A6,Revisión!$A$2:$L$703,6,FALSE) -> #N/A | I6: =VLOOKUP(A6,Revisión!$A$2:$L$703,7,FALSE) -> #N/A | J6: =VLOOKUP(A6,Revisión!$A$2:$L$703,8,FALSE) -> #N/A | K6: =VLOOKUP(A6,Revisión!$A$2:$L$703,9,FALSE) -> #N/A | L6: =VLOOKUP(A6,Revisión!$A$2:$L$703,10,FALSE) -> #N/A | M6: =VLOOKUP(A6,Revisión!$A$2:$L$703,11,FALSE) -> #N/A | N6: =IF(E6="Coinciden",D6,IF(E6="Revisar",VLOOKUP(A6,Revisión!$A$2:$L$703,12,FALSE),"")) -> Abelmoschus manihot
A7: Abutilon.depauperatum | B7: Abutilon depauperatum | C7: Pseudabutilon depauperatum | D7: Pseudabutilon depauperatum | E7: Revisar | F7: Coinciden rWCVP y WFO; GBIF es diferente | H7: =VLOOKUP(A7,Revisión!$A$2:$L$703,6,FALSE) -> Pseudabutilon depauperatum | I7: =VLOOKUP(A7,Revisión!$A$2:$L$703,7,FALSE) -> Pseudabutilon depauperatum | J7: =VLOOKUP(A7,Revisión!$A$2:$L$703,8,FALSE) -> Pseudabutilon depauperatum | K7: =VLOOKUP(A7,Revisión!$A$2:$L$703,9,FALSE) -> - | L7: =VLOOKUP(A7,Revisión!$A$2:$L$703,10,FALSE) -> - | M7: =VLOOKUP(A7,Revisión!$A$2:$L$703,11,FALSE) -> 3 | N7: =IF(E7="Coinciden",D7,IF(E7="Revisar",VLOOKUP(A7,Revisión!$A$2:$L$703,12,FALSE),"")) -> Pseudabutilon depauperatum
A8: Abutilon.terminale | B8: Abutilon terminale | C8: Abutilon terminale | D8: Abutilon terminale | E8: Coinciden | F8: Coinciden las tres fuentes | H8: =VLOOKUP(A8,Revisión!$A$2:$L$703,6,FALSE) -> #N/A | I8: =VLOOKUP(A8,Revisión!$A$2:$L$703,7,FALSE) -> #N/A | J8: =VLOOKUP(A8,Revisión!$A$2:$L$703,8,FALSE) -> #N/A | K8: =VLOOKUP(A8,Revisión!$A$2:$L$703,9,FALSE) -> #N/A | L8: =VLOOKUP(A8,Revisión!$A$2:$L$703,10,FALSE) -> #N/A | M8: =VLOOKUP(A8,Revisión!$A$2:$L$703,11,FALSE) -> #N/A | N8: =IF(E8="Coinciden",D8,IF(E8="Revisar",VLOOKUP(A8,Revisión!$A$2:$L$703,12,FALSE),"")) -> Abutilon terminale
A9: Abutilon.theophrasti | B9: Abutilon theophrasti | C9: Abutilon theophrasti | D9: Abutilon theophrasti | E9: Coinciden | F9: Coinciden las tres fuentes | H9: =VLOOKUP(A9,Revisión!$A$2:$L$703,6,FALSE) -> #N/A | I9: =VLOOKUP(A9,Revisión!$A$2:$L$703,7,FALSE) -> #N/A | J9: =VLOOKUP(A9,Revisión!$A$2:$L$703,8,FALSE) -> #N/A | K9: =VLOOKUP(A9,Revisión!$A$2:$L$703,9,FALSE) -> #N/A | L9: =VLOOKUP(A9,Revisión!$A$2:$L$703,10,FALSE) -> #N/A | M9: =VLOOKUP(A9,Revisión!$A$2:$L$703,11,FALSE) -> #N/A | N9: =IF(E9="Coinciden",D9,IF(E9="Revisar",VLOOKUP(A9,Revisión!$A$2:$L$703,12,FALSE),"")) -> Abutilon theophrasti
A10: Acacia.insulae-iacobi | B10: Vachellia insulae-iacobi | C10: Vachellia insulae-iacobi | D10: Vachellia insulae-iacobi | E10: Coinciden | F10: Coinciden las tres fuentes | H10: =VLOOKUP(A10,Revisión!$A$2:$L$703,6,FALSE) -> #N/A | I10: =VLOOKUP(A10,Revisión!$A$2:$L$703,7,FALSE) -> #N/A | J10: =VLOOKUP(A10,Revisión!$A$2:$L$703,8,FALSE) -> #N/A | K10: =VLOOKUP(A10,Revisión!$A$2:$L$703,9,FALSE) -> #N/A | L10: =VLOOKUP(A10,Revisión!$A$2:$L$703,10,FALSE) -> #N/A | M10: =VLOOKUP(A10,Revisión!$A$2:$L$703,11,FALSE) -> #N/A | N10: =IF(E10="Coinciden",D10,IF(E10="Revisar",VLOOKUP(A10,Revisión!$A$2:$L$703,12,FALSE),"")) -> Vachellia insulae-iacobi
A11: Acacia.macracantha | B11: Vachellia macracantha | C11: Vachellia macracantha | D11: Vachellia macracantha | E11: Coinciden | F11: Coinciden las tres fuentes | H11: =VLOOKUP(A11,Revisión!$A$2:$L$703,6,FALSE) -> Vachellia macracantha | I11: =VLOOKUP(A11,Revisión!$A$2:$L$703,7,FALSE) -> Vachellia macracantha | J11: =VLOOKUP(A11,Revisión!$A$2:$L$703,8,FALSE) -> Vachellia macracantha | K11: =VLOOKUP(A11,Revisión!$A$2:$L$703,9,FALSE) -> - | L11: =VLOOKUP(A11,Revisión!$A$2:$L$703,10,FALSE) -> - | M11: =VLOOKUP(A11,Revisión!$A$2:$L$703,11,FALSE) -> 3 | N11: =IF(E11="Coinciden",D11,IF(E11="Revisar",VLOOKUP(A11,Revisión!$A$2:$L$703,12,FALSE),"")) -> Vachellia macracantha
A12: Acaena.pinnatifida | B12: Acaena pinnatifida | D12: Acaena pinnatifida | E12: Revisar | F12: Coinciden GBIF y WFO; rWCVP sin resultado | H12: =VLOOKUP(A12,Revisión!$A$2:$L$703,6,FALSE) -> Acaena pinnatifida | I12: =VLOOKUP(A12,Revisión!$A$2:$L$703,7,FALSE) -> Acaena pinnatifida | J12: =VLOOKUP(A12,Revisión!$A$2:$L$703,8,FALSE) -> Acaena pinnatifida | K12: =VLOOKUP(A12,Revisión!$A$2:$L$703,9,FALSE) -> - | L12: =VLOOKUP(A12,Revisión!$A$2:$L$703,10,FALSE) -> - | M12: =VLOOKUP(A12,Revisión!$A$2:$L$703,11,FALSE) -> 3 | N12: =IF(E12="Coinciden",D12,IF(E12="Revisar",VLOOKUP(A12,Revisión!$A$2:$L$703,12,FALSE),"")) -> Acaena pinnatifida
A13: Acanthostachys.strobilaceae | B13: Acanthostachys strobilacea | C13: Acanthostachys strobilacea | D13: Acanthostachys strobilacea | E13: Coinciden | F13: Coinciden las tres fuentes | H13: =VLOOKUP(A13,Revisión!$A$2:$L$703,6,FALSE) -> Acanthostachys strobilacea | I13: =VLOOKUP(A13,Revisión!$A$2:$L$703,7,FALSE) -> Acanthostachys strobilacea | J13: =VLOOKUP(A13,Revisión!$A$2:$L$703,8,FALSE) -> Acanthostachys strobilacea | K13: =VLOOKUP(A13,Revisión!$A$2:$L$703,9,FALSE) -> - | L13: =VLOOKUP(A13,Revisión!$A$2:$L$703,10,FALSE) -> - | M13: =VLOOKUP(A13,Revisión!$A$2:$L$703,11,FALSE) -> 3 | N13: =IF(E13="Coinciden",D13,IF(E13="Revisar",VLOOKUP(A13,Revisión!$A$2:$L$703,12,FALSE),"")) -> Acanthostachys strobilacea
A14: Acanthus.spinosus | B14: Acanthus spinosus | C14: Acanthus spinosus | D14: Acanthus spinosus | E14: Coinciden | F14: Coinciden las tres fuentes | H14: =VLOOKUP(A14,Revisión!$A$2:$L$703,6,FALSE) -> #N/A | I14: =VLOOKUP(A14,Revisión!$A$2:$L$703,7,FALSE) -> #N/A | J14: =VLOOKUP(A14,Revisión!$A$2:$L$703,8,FALSE) -> #N/A | K14: =VLOOKUP(A14,Revisión!$A$2:$L$703,9,FALSE) -> #N/A | L14: =VLOOKUP(A14,Revisión!$A$2:$L$703,10,FALSE) -> #N/A | M14: =VLOOKUP(A14,Revisión!$A$2:$L$703,11,FALSE) -> #N/A | N14: =IF(E14="Coinciden",D14,IF(E14="Revisar",VLOOKUP(A14,Revisión!$A$2:$L$703,12,FALSE),"")) -> Acanthus spinosus
A15: Acer.ukurunduense | B15: Acer ukurunduense | C15: Acer ukurunduense | D15: Acer ukurunduense | E15: Coinciden | F15: Coinciden las tres fuentes | H15: =VLOOKUP(A15,Revisión!$A$2:$L$703,6,FALSE) -> #N/A | I15: =VLOOKUP(A15,Revisión!$A$2:$L$703,7,FALSE) -> #N/A | J15: =VLOOKUP(A15,Revisión!$A$2:$L$703,8,FALSE) -> #N/A | K15: =VLOOKUP(A15,Revisión!$A$2:$L$703,9,FALSE) -> #N/A | L15: =VLOOKUP(A15,Revisión!$A$2:$L$703,10,FALSE) -> #N/A | M15: =VLOOKUP(A15,Revisión!$A$2:$L$703,11,FALSE) -> #N/A | N15: =IF(E15="Coinciden",D15,IF(E15="Revisar",VLOOKUP(A15,Revisión!$A$2:$L$703,12,FALSE),"")) -> Acer ukurunduense
A16: Acer.shirasawanum | B16: Acer shirasawanum | C16: Acer shirasawanum | D16: Acer shirasawanum | E16: Coinciden | F16: Coinciden las tres fuentes | H16: =VLOOKUP(A16,Revisión!$A$2:$L$703,6,FALSE) -> #N/A | I16: =VLOOKUP(A16,Revisión!$A$2:$L$703,7,FALSE) -> #N/A | J16: =VLOOKUP(A16,Revisión!$A$2:$L$703,8,FALSE) -> #N/A | K16: =VLOOKUP(A16,Revisión!$A$2:$L$703,9,FALSE) -> #N/A | L16: =VLOOKUP(A16,Revisión!$A$2:$L$703,10,FALSE) -> #N/A | M16: =VLOOKUP(A16,Revisión!$A$2:$L$703,11,FALSE) -> #N/A | N16: =IF(E16="Coinciden",D16,IF(E16="Revisar",VLOOKUP(A16,Revisión!$A$2:$L$703,12,FALSE),"")) -> Acer shirasawanum
A17: Acer.rufinerve | B17: Acer rufinerve | C17: Acer rufinerve | D17: Acer rufinerve | E17: Coinciden | F17: Coinciden las tres fuentes | H17: =VLOOKUP(A17,Revisión!$A$2:$L$703,6,FALSE) -> #N/A | I17: =VLOOKUP(A17,Revisión!$A$2:$L$703,7,FALSE) -> #N/A | J17: =VLOOKUP(A17,Revisión!$A$2:$L$703,8,FALSE) -> #N/A | K17: =VLOOKUP(A17,Revisión!$A$2:$L$703,9,FALSE) -> #N/A | L17: =VLOOKUP(A17,Revisión!$A$2:$L$703,10,FALSE) -> #N/A | M17: =VLOOKUP(A17,Revisión!$A$2:$L$703,11,FALSE) -> #N/A | N17: =IF(E17="Coinciden",D17,IF(E17="Revisar",VLOOKUP(A17,Revisión!$A$2:$L$703,12,FALSE),"")) -> Acer rufinerve
A18: Acer.saccharinum | B18: Acer saccharinum | C18: Acer saccharinum | D18: Acer saccharinum | E18: Coinciden | F18: Coinciden las tres fuentes | H18: =VLOOKUP(A18,Revisión!$A$2:$L$703,6,FALSE) -> #N/A | I18: =VLOOKUP(A18,Revisión!$A$2:$L$703,7,FALSE) -> #N/A | J18: =VLOOKUP(A18,Revisión!$A$2:$L$703,8,FALSE) -> #N/A | K18: =VLOOKUP(A18,Revisión!$A$2:$L$703,9,FALSE) -> #N/A | L18: =VLOOKUP(A18,Revisión!$A$2:$L$703,10,FALSE) -> #N/A | M18: =VLOOKUP(A18,Revisión!$A$2:$L$703,11,FALSE) -> #N/A | N18: =IF(E18="Coinciden",D18,IF(E18="Revisar",VLOOKUP(A18,Revisión!$A$2:$L$703,12,FALSE),"")) -> Acer saccharinum
A19: Acer.insulae | C19: Acer insulare | D19: Acer insulare | E19: Revisar | F19: Coinciden rWCVP y WFO; GBIF sin resultado | H19: =VLOOKUP(A19,Revisión!$A$2:$L$703,6,FALSE) -> Acer insulare | I19: =VLOOKUP(A19,Revisión!$A$2:$L$703,7,FALSE) -> Acer insulare | J19: =VLOOKUP(A19,Revisión!$A$2:$L$703,8,FALSE) -> Acer insulare | K19: =VLOOKUP(A19,Revisión!$A$2:$L$703,9,FALSE) -> - | L19: =VLOOKUP(A19,Revisión!$A$2:$L$703,10,FALSE) -> - | M19: =VLOOKUP(A19,Revisión!$A$2:$L$703,11,FALSE) -> 3 | N19: =IF(E19="Coinciden",D19,IF(E19="Revisar",VLOOKUP(A19,Revisión!$A$2:$L$703,12,FALSE),"")) -> Acer insulare
A20: Acer.japonicum | B20: Acer japonicum | C20: Acer japonicum | D20: Acer japonicum | E20: Coinciden | F20: Coinciden las tres fuentes | H20: =VLOOKUP(A20,Revisión!$A$2:$L$703,6,FALSE) -> #N/A | I20: =VLOOKUP(A20,Revisión!$A$2:$L$703,7,FALSE) -> #N/A | J20: =VLOOKUP(A20,Revisión!$A$2:$L$703,8,FALSE) -> #N/A | K20: =VLOOKUP(A20,Revisión!$A$2:$L$703,9,FALSE) -> #N/A | L20: =VLOOKUP(A20,Revisión!$A$2:$L$703,10,FALSE) -> #N/A | M20: =VLOOKUP(A20,Revisión!$A$2:$L$703,11,FALSE) -> #N/A | N20: =IF(E20="Coinciden",D20,IF(E20="Revisar",VLOOKUP(A20,Revisión!$A$2:$L$703,12,FALSE),"")) -> Acer japonicum
A21: Acer.carpinifolium | B21: Acer carpinifolium | C21: Acer carpinifolium | D21: Acer carpinifolium | E21: Coinciden | F21: Coinciden las tres fuentes | H21: =VLOOKUP(A21,Revisión!$A$2:$L$703,6,FALSE) -> #N/A | I21: =VLOOKUP(A21,Revisión!$A$2:$L$703,7,FALSE) -> #N/A | J21: =VLOOKUP(A21,Revisión!$A$2:$L$703,8,FALSE) -> #N/A | K21: =VLOOKUP(A21,Revisión!$A$2:$L$703,9,FALSE) -> #N/A | L21: =VLOOKUP(A21,Revisión!$A$2:$L$703,10,FALSE) -> #N/A | M21: =VLOOKUP(A21,Revisión!$A$2:$L$703,11,FALSE) -> #N/A | N21: =IF(E21="Coinciden",D21,IF(E21="Revisar",VLOOKUP(A21,Revisión!$A$2:$L$703,12,FALSE),"")) -> Acer carpinifolium
A22: Acer.negundo | B22: Acer negundo | C22: Acer negundo | D22: Acer negundo | E22: Coinciden | F22: Coinciden las tres fuentes | H22: =VLOOKUP(A22,Revisión!$A$2:$L$703,6,FALSE) -> #N/A | I22: =VLOOKUP(A22,Revisión!$A$2:$L$703,7,FALSE) -> #N/A | J22: =VLOOKUP(A22,Revisión!$A$2:$L$703,8,FALSE) -> #N/A | K22: =VLOOKUP(A22,Revisión!$A$2:$L$703,9,FALSE) -> #N/A | L22: =VLOOKUP(A22,Revisión!$A$2:$L$703,10,FALSE) -> #N/A | M22: =VLOOKUP(A22,Revisión!$A$2:$L$703,11,FALSE) -> #N/A | N22: =IF(E22="Coinciden",D22,IF(E22="Revisar",VLOOKUP(A22,Revisión!$A$2:$L$703,12,FALSE),"")) -> Acer negundo
A23: Achillea.alpina. | B23: Achillea alpina | C23: Achillea alpina | D23: Achillea alpina | E23: Coinciden | F23: Coinciden las tres fuentes | H23: =VLOOKUP(A23,Revisión!$A$2:$L$703,6,FALSE) -> #N/A | I23: =VLOOKUP(A23,Revisión!$A$2:$L$703,7,FALSE) -> #N/A | J23: =VLOOKUP(A23,Revisión!$A$2:$L$703,8,FALSE) -> #N/A | K23: =VLOOKUP(A23,Revisión!$A$2:$L$703,9,FALSE) -> #N/A | L23: =VLOOKUP(A23,Revisión!$A$2:$L$703,10,FALSE) -> #N/A | M23: =VLOOKUP(A23,Revisión!$A$2:$L$703,11,FALSE) -> #N/A | N23: =IF(E23="Coinciden",D23,IF(E23="Revisar",VLOOKUP(A23,Revisión!$A$2:$L$703,12,FALSE),"")) -> Achillea alpina
A24: Achillea.millefolium | B24: Achillea millefolium | C24: Achillea millefolium | D24: Achillea millefolium | E24: Coinciden | F24: Coinciden las tres fuentes | H24: =VLOOKUP(A24,Revisión!$A$2:$L$703,6,FALSE) -> #N/A | I24: =VLOOKUP(A24,Revisión!$A$2:$L$703,7,FALSE) -> #N/A | J24: =VLOOKUP(A24,Revisión!$A$2:$L$703,8,FALSE) -> #N/A | K24: =VLOOKUP(A24,Revisión!$A$2:$L$703,9,FALSE) -> #N/A | L24: =VLOOKUP(A24,Revisión!$A$2:$L$703,10,FALSE) -> #N/A | M24: =VLOOKUP(A24,Revisión!$A$2:$L$703,11,FALSE) -> #N/A | N24: =IF(E24="Coinciden",D24,IF(E24="Revisar",VLOOKUP(A24,Revisión!$A$2:$L$703,12,FALSE),"")) -> Achillea millefolium
A25: Achyranthes.bidentata | B25: Achyranthes bidentata | C25: Achyranthes bidentata | D25: Achyranthes bidentata | E25: Coinciden | F25: Coinciden las tres fuentes | H25: =VLOOKUP(A25,Revisión!$A$2:$L$703,6,FALSE) -> #N/A | I25: =VLOOKUP(A25,Revisión!$A$2:$L$703,7,FALSE) -> #N/A | J25: =VLOOKUP(A25,Revisión!$A$2:$L$703,8,FALSE) -> #N/A | K25: =VLOOKUP(A25,Revisión!$A$2:$L$703,9,FALSE) -> #N/A | L25: =VLOOKUP(A25,Revisión!$A$2:$L$703,10,FALSE) -> #N/A | M25: =VLOOKUP(A25,Revisión!$A$2:$L$703,11,FALSE) -> #N/A | N25: =IF(E25="Coinciden",D25,IF(E25="Revisar",VLOOKUP(A25,Revisión!$A$2:$L$703,12,FALSE),"")) -> Achyranthes bidentata
A26: Achyrocline.satureoides | C26: Achyrocline saturejoides | D26: Achyrocline satureioides | E26: Revisar | F26: Falta resultado en una o más fuentes | H26: =VLOOKUP(A26,Revisión!$A$2:$L$703,6,FALSE) -> Achyrocline saturejoides | I26: =VLOOKUP(A26,Revisión!$A$2:$L$703,7,FALSE) -> Achyrocline saturejoides | J26: =VLOOKUP(A26,Revisión!$A$2:$L$703,8,FALSE) -> Achyrocline saturejoides | K26: =VLOOKUP(A26,Revisión!$A$2:$L$703,9,FALSE) -> - | L26: =VLOOKUP(A26,Revisión!$A$2:$L$703,10,FALSE) -> - | M26: =VLOOKUP(A26,Revisión!$A$2:$L$703,11,FALSE) -> 3 | N26: =IF(E26="Coinciden",D26,IF(E26="Revisar",VLOOKUP(A26,Revisión!$A$2:$L$703,12,FALSE),"")) -> Achyrocline saturejoides
A27: Aciphylla.glacialis | B27: Aciphylla glacialis | C27: Aciphylla glacialis | D27: Aciphylla glacialis | E27: Coinciden | F27: Coinciden las tres fuentes | H27: =VLOOKUP(A27,Revisión!$A$2:$L$703,6,FALSE) -> #N/A | I27: =VLOOKUP(A27,Revisión!$A$2:$L$703,7,FALSE) -> #N/A | J27: =VLOOKUP(A27,Revisión!$A$2:$L$703,8,FALSE) -> #N/A | K27: =VLOOKUP(A27,Revisión!$A$2:$L$703,9,FALSE) -> #N/A | L27: =VLOOKUP(A27,Revisión!$A$2:$L$703,10,FALSE) -> #N/A | M27: =VLOOKUP(A27,Revisión!$A$2:$L$703,11,FALSE) -> #N/A | N27: =IF(E27="Coinciden",D27,IF(E27="Revisar",VLOOKUP(A27,Revisión!$A$2:$L$703,12,FALSE),"")) -> Aciphylla glacialis
A28: Aciphylla.scott-thompsoni | C28: Aciphylla scott-thomsonii | D28: Aciphylla scott-thomsonii | E28: Revisar | F28: Coinciden rWCVP y WFO; GBIF sin resultado | H28: =VLOOKUP(A28,Revisión!$A$2:$L$703,6,FALSE) -> Aciphylla scott-thomsonii | I28: =VLOOKUP(A28,Revisión!$A$2:$L$703,7,FALSE) -> Aciphylla scott-thomsonii | J28: =VLOOKUP(A28,Revisión!$A$2:$L$703,8,FALSE) -> Aciphylla scott-thomsonii | K28: =VLOOKUP(A28,Revisión!$A$2:$L$703,9,FALSE) -> - | L28: =VLOOKUP(A28,Revisión!$A$2:$L$703,10,FALSE) -> - | M28: =VLOOKUP(A28,Revisión!$A$2:$L$703,11,FALSE) -> 3 | N28: =IF(E28="Coinciden",D28,IF(E28="Revisar",VLOOKUP(A28,Revisión!$A$2:$L$703,12,FALSE),"")) -> Aciphylla scott-thomsonii
A29: Aciphylla.simplicifolia | B29: Aciphylla simplicifolia | C29: Aciphylla simplicifolia | D29: Aciphylla simplicifolia | E29: Coinciden | F29: Coinciden las tres fuentes | H29: =VLOOKUP(A29,Revisión!$A$2:$L$703,6,FALSE) -> #N/A | I29: =VLOOKUP(A29,Revisión!$A$2:$L$703,7,FALSE) -> #N/A | J29: =VLOOKUP(A29,Revisión!$A$2:$L$703,8,FALSE) -> #N/A | K29: =VLOOKUP(A29,Revisión!$A$2:$L$703,9,FALSE) -> #N/A | L29: =VLOOKUP(A29,Revisión!$A$2:$L$703,10,FALSE) -> #N/A | M29: =VLOOKUP(A29,Revisión!$A$2:$L$703,11,FALSE) -> #N/A | N29: =IF(E29="Coinciden",D29,IF(E29="Revisar",VLOOKUP(A29,Revisión!$A$2:$L$703,12,FALSE),"")) -> Aciphylla simplicifolia
A30: Aciphylla.subflavellata | C30: Aciphylla subflabellata | D30: Aciphylla subflabellata | E30: Revisar | F30: Coinciden rWCVP y WFO; GBIF sin resultado | H30: =VLOOKUP(A30,Revisión!$A$2:$L$703,6,FALSE) -> Aciphylla subflabellata | I30: =VLOOKUP(A30,Revisión!$A$2:$L$703,7,FALSE) -> Aciphylla subflabellata | J30: =VLOOKUP(A30,Revisión!$A$2:$L$703,8,FALSE) -> Aciphylla subflabellata | K30: =VLOOKUP(A30,Revisión!$A$2:$L$703,9,FALSE) -> - | L30: =VLOOKUP(A30,Revisión!$A$2:$L$703,10,FALSE) -> - | M30: =VLOOKUP(A30,Revisión!$A$2:$L$703,11,FALSE) -> 3 | N30: =IF(E30="Coinciden",D30,IF(E30="Revisar",VLOOKUP(A30,Revisión!$A$2:$L$703,12,FALSE),"")) -> Aciphylla subflabellata
A31: Aconitum.japonicum | B31: Aconitum japonicum | C31: Aconitum japonicum | D31: Aconitum japonicum | E31: Coinciden | F31: Coinciden las tres fuentes | H31: =VLOOKUP(A31,Revisión!$A$2:$L$703,6,FALSE) -> #N/A | I31: =VLOOKUP(A31,Revisión!$A$2:$L$703,7,FALSE) -> #N/A | J31: =VLOOKUP(A31,Revisión!$A$2:$L$703,8,FALSE) -> #N/A | K31: =VLOOKUP(A31,Revisión!$A$2:$L$703,9,FALSE) -> #N/A | L31: =VLOOKUP(A31,Revisión!$A$2:$L$703,10,FALSE) -> #N/A | M31: =VLOOKUP(A31,Revisión!$A$2:$L$703,11,FALSE) -> #N/A | N31: =IF(E31="Coinciden",D31,IF(E31="Revisar",VLOOKUP(A31,Revisión!$A$2:$L$703,12,FALSE),"")) -> Aconitum japonicum
A32: Aconitum.senanense | B32: Aconitum senanense | C32: Aconitum senanense | D32: Aconitum senanense | E32: Coinciden | F32: Coinciden las tres fuentes | H32: =VLOOKUP(A32,Revisión!$A$2:$L$703,6,FALSE) -> #N/A | I32: =VLOOKUP(A32,Revisión!$A$2:$L$703,7,FALSE) -> #N/A | J32: =VLOOKUP(A32,Revisión!$A$2:$L$703,8,FALSE) -> #N/A | K32: =VLOOKUP(A32,Revisión!$A$2:$L$703,9,FALSE) -> #N/A | L32: =VLOOKUP(A32,Revisión!$A$2:$L$703,10,FALSE) -> #N/A | M32: =VLOOKUP(A32,Revisión!$A$2:$L$703,11,FALSE) -> #N/A | N32: =IF(E32="Coinciden",D32,IF(E32="Revisar",VLOOKUP(A32,Revisión!$A$2:$L$703,12,FALSE),"")) -> Aconitum senanense
A33: Aconitum.columbianum | B33: Aconitum columbianum | C33: Aconitum columbianum | D33: Aconitum columbianum | E33: Coinciden | F33: Coinciden las tres fuentes | H33: =VLOOKUP(A33,Revisión!$A$2:$L$703,6,FALSE) -> #N/A | I33: =VLOOKUP(A33,Revisión!$A$2:$L$703,7,FALSE) -> #N/A | J33: =VLOOKUP(A33,Revisión!$A$2:$L$703,8,FALSE) -> #N/A | K33: =VLOOKUP(A33,Revisión!$A$2:$L$703,9,FALSE) -> #N/A | L33: =VLOOKUP(A33,Revisión!$A$2:$L$703,10,FALSE) -> #N/A | M33: =VLOOKUP(A33,Revisión!$A$2:$L$703,11,FALSE) -> #N/A | N33: =IF(E33="Coinciden",D33,IF(E33="Revisar",VLOOKUP(A33,Revisión!$A$2:$L$703,12,FALSE),"")) -> Aconitum columbianum
A34: Aconitum.japonicum.montanum | B34: Aconitum japonicum subsp. japonicum | C34: Aconitum japonicum subsp. japonicum | D34: Aconitum japonicum | E34: Revisar | F34: Coinciden GBIF y rWCVP; WFO es diferente | H34: =VLOOKUP(A34,Revisión!$A$2:$L$703,6,FALSE) -> Aconitum japonicum subsp. japonicum | I34: =VLOOKUP(A34,Revisión!$A$2:$L$703,7,FALSE) -> - | J34: =VLOOKUP(A34,Revisión!$A$2:$L$703,8,FALSE) -> Aconitum japonicum subsp. japonicum | K34: =VLOOKUP(A34,Revisión!$A$2:$L$703,9,FALSE) -> - | L34: =VLOOKUP(A34,Revisión!$A$2:$L$703,10,FALSE) -> - | M34: =VLOOKUP(A34,Revisión!$A$2:$L$703,11,FALSE) -> 2 | N34: =IF(E34="Coinciden",D34,IF(E34="Revisar",VLOOKUP(A34,Revisión!$A$2:$L$703,12,FALSE),"")) -> Aconitum japonicum subsp. japonicum
A35: Actea.alba | C35: Actaea rubra | D35: Actaea rubra | E35: Revisar | F35: Coinciden rWCVP y WFO; GBIF sin resultado | H35: =VLOOKUP(A35,Revisión!$A$2:$L$703,6,FALSE) -> Actaea rubra | I35: =VLOOKUP(A35,Revisión!$A$2:$L$703,7,FALSE) -> Actaea rubra | J35: =VLOOKUP(A35,Revisión!$A$2:$L$703,8,FALSE) -> Actaea rubra | K35: =VLOOKUP(A35,Revisión!$A$2:$L$703,9,FALSE) -> - | L35: =VLOOKUP(A35,Revisión!$A$2:$L$703,10,FALSE) -> - | M35: =VLOOKUP(A35,Revisión!$A$2:$L$703,11,FALSE) -> 3 | N35: =IF(E35="Coinciden",D35,IF(E35="Revisar",VLOOKUP(A35,Revisión!$A$2:$L$703,12,FALSE),"")) -> Actaea rubra
A36: Actinidia.arguta | B36: Actinidia arguta | C36: Actinidia arguta | D36: Actinidia arguta | E36: Coinciden | F36: Coinciden las tres fuentes | H36: =VLOOKUP(A36,Revisión!$A$2:$L$703,6,FALSE) -> #N/A | I36: =VLOOKUP(A36,Revisión!$A$2:$L$703,7,FALSE) -> #N/A | J36: =VLOOKUP(A36,Revisión!$A$2:$L$703,8,FALSE) -> #N/A | K36: =VLOOKUP(A36,Revisión!$A$2:$L$703,9,FALSE) -> #N/A | L36: =VLOOKUP(A36,Revisión!$A$2:$L$703,10,FALSE) -> #N/A | M36: =VLOOKUP(A36,Revisión!$A$2:$L$703,11,FALSE) -> #N/A | N36: =IF(E36="Coinciden",D36,IF(E36="Revisar",VLOOKUP(A36,Revisión!$A$2:$L$703,12,FALSE),"")) -> Actinidia arguta
A37: Actinidia.rufa | B37: Actinidia rufa | C37: Actinidia rufa | D37: Actinidia rufa | E37: Coinciden | F37: Coinciden las tres fuentes | H37: =VLOOKUP(A37,Revisión!$A$2:$L$703,6,FALSE) -> #N/A | I37: =VLOOKUP(A37,Revisión!$A$2:$L$703,7,FALSE) -> #N/A | J37: =VLOOKUP(A37,Revisión!$A$2:$L$703,8,FALSE) -> #N/A | K37: =VLOOKUP(A37,Revisión!$A$2:$L$703,9,FALSE) -> #N/A | L37: =VLOOKUP(A37,Revisión!$A$2:$L$703,10,FALSE) -> #N/A | M37: =VLOOKUP(A37,Revisión!$A$2:$L$703,11,FALSE) -> #N/A | N37: =IF(E37="Coinciden",D37,IF(E37="Revisar",VLOOKUP(A37,Revisión!$A$2:$L$703,12,FALSE),"")) -> Actinidia rufa
A38: Actinomeris.alternifolia | B38: Verbesina alternifolia | C38: Verbesina alternifolia | D38: Verbesina alternifolia | E38: Coinciden | F38: Coinciden las tres fuentes | H38: =VLOOKUP(A38,Revisión!$A$2:$L$703,6,FALSE) -> #N/A | I38: =VLOOKUP(A38,Revisión!$A$2:$L$703,7,FALSE) -> #N/A | J38: =VLOOKUP(A38,Revisión!$A$2:$L$703,8,FALSE) -> #N/A | K38: =VLOOKUP(A38,Revisión!$A$2:$L$703,9,FALSE) -> #N/A | L38: =VLOOKUP(A38,Revisión!$A$2:$L$703,10,FALSE) -> #N/A | M38: =VLOOKUP(A38,Revisión!$A$2:$L$703,11,FALSE) -> #N/A | N38: =IF(E38="Coinciden",D38,IF(E38="Revisar",VLOOKUP(A38,Revisión!$A$2:$L$703,12,FALSE),"")) -> Verbesina alternifolia
A39: Adenocarpus.foliosus | C39: Adenocarpus complicatus subsp. aureus | D39: Adenocarpus foliolosus | E39: Revisar | F39: Falta resultado en una o más fuentes | H39: =VLOOKUP(A39,Revisión!$A$2:$L$703,6,FALSE) -> Adenocarpus foliolosus | I39: =VLOOKUP(A39,Revisión!$A$2:$L$703,7,FALSE) -> Adenocarpus foliolosus | J39: =VLOOKUP(A39,Revisión!$A$2:$L$703,8,FALSE) -> Adenocarpus foliolosus | K39: =VLOOKUP(A39,Revisión!$A$2:$L$703,9,FALSE) -> - | L39: =VLOOKUP(A39,Revisión!$A$2:$L$703,10,FALSE) -> - | M39: =VLOOKUP(A39,Revisión!$A$2:$L$703,11,FALSE) -> 3 | N39: =IF(E39="Coinciden",D39,IF(E39="Revisar",VLOOKUP(A39,Revisión!$A$2:$L$703,12,FALSE),"")) -> Adenocarpus foliolosus
A40: Adenocarpus.viscosus | B40: Adenocarpus viscosus | C40: Adenocarpus viscosus | D40: Adenocarpus viscosus | E40: Coinciden | F40: Coinciden las tres fuentes | H40: =VLOOKUP(A40,Revisión!$A$2:$L$703,6,FALSE) -> #N/A | I40: =VLOOKUP(A40,Revisión!$A$2:$L$703,7,FALSE) -> #N/A | J40: =VLOOKUP(A40,Revisión!$A$2:$L$703,8,FALSE) -> #N/A | K40: =VLOOKUP(A40,Revisión!$A$2:$L$703,9,FALSE) -> #N/A | L40: =VLOOKUP(A40,Revisión!$A$2:$L$703,10,FALSE) -> #N/A | M40: =VLOOKUP(A40,Revisión!$A$2:$L$703,11,FALSE) -> #N/A | N40: =IF(E40="Coinciden",D40,IF(E40="Revisar",VLOOKUP(A40,Revisión!$A$2:$L$703,12,FALSE),"")) -> Adenocarpus viscosus
...

Sheet Revisión
B1: DATOS ORIGINALES | F1: DATOS NUEVOS | M1: -
A2: Genero.especie | B2: Nombre_aceptado_GBIF | C2: Nombre_aceptado_rWCVP | D2: Nombre_aceptado_WFO | E2: Detalle_comparacion_inicial | F2: Nombre_aceptado_GBIF | G2: Nombre_aceptado_WFO | H2: Nombre_aceptado_POWO | I2: Nombre_aceptado_COL (www.catalogueoflife.org) | J2: Nombre_aceptado_WP (www.worldplants.de) | K2: N° de fuentes que coinciden | L2: Especie actual | M2: Referencia extra
A3: Abelia.grandiflora | B3: Abelia chinensis | E3: Falta resultado en una o más fuentes | F3: Abelia × grandiflora | G3: Abelia × grandiflora | H3: Abelia × grandiflora | I3: - | J3: - | K3: 3 | L3: Abelia × grandiflora | M3: -
A4: Abelia.serrata | B4: Diabelia serrata | C4: Diabelia serrata | D4: Linnaea serrata | E4: Coinciden GBIF y rWCVP; WFO es diferente | F4: Diabelia serrata | G4: Diabelia serrata | H4: Diabelia serrata | I4: - | J4: - | K4: 3 | L4: Diabelia serrata | M4: -
A5: Abutilon.depauperatum | B5: Abutilon depauperatum | C5: Pseudabutilon depauperatum | D5: Pseudabutilon depauperatum | E5: Coinciden rWCVP y WFO; GBIF es diferente | F5: Pseudabutilon depauperatum | G5: Pseudabutilon depauperatum | H5: Pseudabutilon depauperatum | I5: - | J5: - | K5: 3 | L5: Pseudabutilon depauperatum | M5: -
A6: Acacia insulae-iacobi | F6: Vachellia insulae-iacobi | G6: Vachellia insulae-iacobi | H6: Vachellia insulae-iacobi | I6: - | J6: - | K6: 3 | L6: Vachellia insulae-iacobi | M6: -
A7: Acacia.macracantha | F7: Vachellia macracantha | G7: Vachellia macracantha | H7: Vachellia macracantha | I7: - | J7: - | K7: 3 | L7: Vachellia macracantha | M7: -
A8: Acaena.pinnatifida | B8: Acaena pinnatifida | D8: Acaena pinnatifida | E8: Coinciden GBIF y WFO; rWCVP sin resultado | F8: Acaena pinnatifida | G8: Acaena pinnatifida | H8: Acaena pinnatifida | I8: - | J8: - | K8: 3 | L8: Acaena pinnatifida | M8: -
A9: Acanthostachys.strobilaceae | F9: Acanthostachys strobilacea | G9: Acanthostachys strobilacea | H9: Acanthostachys strobilacea | I9: - | J9: - | K9: 3 | L9: Acanthostachys strobilacea | M9: -
A10: Acer.insulae | C10: Acer insulare | D10: Acer insulare | E10: Coinciden rWCVP y WFO; GBIF sin resultado | F10: Acer insulare | G10: Acer insulare | H10: Acer insulare | I10: - | J10: - | K10: 3 | L10: Acer insulare | M10: -
A11: Achyrocline.satureoides | C11: Achyrocline saturejoides | D11: Achyrocline satureioides | E11: Falta resultado en una o más fuentes | F11: Achyrocline saturejoides | G11: Achyrocline saturejoides | H11: Achyrocline saturejoides | I11: - | J11: - | K11: 3 | L11: Achyrocline saturejoides | M11: -
A12: Aciphylla.scott-thompsoni | C12: Aciphylla scott-thomsonii | D12: Aciphylla scott-thomsonii | E12: Coinciden rWCVP y WFO; GBIF sin resultado | F12: Aciphylla scott-thomsonii | G12: Aciphylla scott-thomsonii | H12: Aciphylla scott-thomsonii | I12: - | J12: - | K12: 3 | L12: Aciphylla scott-thomsonii | M12: -
A13: Aciphylla.subflavellata | C13: Aciphylla subflabellata | D13: Aciphylla subflabellata | E13: Coinciden rWCVP y WFO; GBIF sin resultado | F13: Aciphylla subflabellata | G13: Aciphylla subflabellata | H13: Aciphylla subflabellata | I13: - | J13: - | K13: 3 | L13: Aciphylla subflabellata | M13: -
A14: Aconitum.japonicum.montanum | B14: Aconitum japonicum subsp. japonicum | C14: Aconitum japonicum subsp. japonicum | D14: Aconitum japonicum | E14: Coinciden GBIF y rWCVP; WFO es diferente | F14: Aconitum japonicum subsp. japonicum | G14: - | H14: Aconitum japonicum subsp. japonicum | I14: - | J14: - | K14: 2 | L14: Aconitum japonicum subsp. japonicum | M14: -
A15: Actea.alba | C15: Actaea rubra | D15: Actaea rubra | E15: Coinciden rWCVP y WFO; GBIF sin resultado | F15: Actaea rubra | G15: Actaea rubra | H15: Actaea rubra | I15: - | J15: - | K15: 3 | L15: Actaea rubra | M15: -
A16: Adenocarpus.foliosus | C16: Adenocarpus complicatus subsp. aureus | D16: Adenocarpus foliolosus | E16: Falta resultado en una o más fuentes | F16: Adenocarpus foliolosus | G16: Adenocarpus foliolosus | H16: Adenocarpus foliolosus | I16: - | J16: - | K16: 3 | L16: Adenocarpus foliolosus | M16: -
A17: Adesmia.brachysemon | C17: Adesmia brachysemeon | D17: Adesmia brachysemeon | E17: Coinciden rWCVP y WFO; GBIF sin resultado | F17: Adesmia brachysemeon | G17: Adesmia brachysemeon | H17: Adesmia brachysemeon | I17: - | J17: - | K17: 3 | L17: Adesmia brachysemeon | M17: -
A18: Adesmia.haemisphaerica | C18: Adesmia hemisphaerica | D18: Adesmia hemisphaerica | E18: Coinciden rWCVP y WFO; GBIF sin resultado | F18: Adesmia hemisphaerica | G18: Adesmia hemisphaerica | H18: Adesmia hemisphaerica | I18: - | J18: - | K18: 3 | L18: Adesmia hemisphaerica | M18: -
A19: Aechmea.paniculigera | B19: Aechmea paniculigera | D19: Aechmea paniculigera | E19: Coinciden GBIF y WFO; rWCVP sin resultado | F19: Aechmea paniculigera | G19: Aechmea paniculigera | H19: Aechmea paniculigera | I19: - | J19: - | K19: 3 | L19: Aechmea paniculigera | M19: -
A20: Aeschynomene.indica | B20: Aeschynomene indica | D20: Aeschynomene indica | E20: Coinciden GBIF y WFO; rWCVP sin resultado | F20: Aeschynomene indica | G20: Aeschynomene indica | H20: Aeschynomene indica | I20: - | J20: - | K20: 3 | L20: Aeschynomene indica | M20: -
A21: Aesculus.camea | E21: Sin resultados en las tres fuentes | F21: Aesculus × carnea | G21: - | H21: Aesculus × carnea | I21: - | J21: - | K21: 2 | L21: Aesculus × carnea | M21: -
A22: Aetheorrina.bulbosa | C22: Sonchus bulbosus | D22: Sonchus bulbosus | E22: Coinciden rWCVP y WFO; GBIF sin resultado | F22: - | G22: Sonchus bulbosus | H22: Sonchus bulbosus | I22: - | J22: - | K22: 2 | L22: Sonchus bulbosus | M22: -
A23: Agastache.scrophulariaefolia | C23: Agastache scrophulariifolia | D23: Agastache scrophulariifolia | E23: Coinciden rWCVP y WFO; GBIF sin resultado | F23: Agastache scrophulariifolia | G23: Agastache scrophulariifolia | H23: Agastache scrophulariifolia | I23: - | J23: - | K23: 3 | L23: Agastache scrophulariifolia | M23: -
A24: Ageratum.conyzoides | B24: Ageratum conyzoides | D24: Ageratum conyzoides | E24: Coinciden GBIF y WFO; rWCVP sin resultado | F24: Ageratum conyzoides | G24: Ageratum conyzoides | H24: Ageratum conyzoides | I24: - | J24: - | K24: 3 | L24: Ageratum conyzoides | M24: -
A25: Ageretina.adenophora | C25: Ageratina adenophora | D25: Ageratina adenophora | E25: Coinciden rWCVP y WFO; GBIF sin resultado | F25: Ageratina adenophora | G25: Ageratina adenophora | H25: Ageratina adenophora | I25: - | J25: - | K25: 3 | L25: Ageratina adenophora | M25: -
A26: Agrimonia.striata | B26: Agrimonia striata | D26: Agrimonia striata | E26: Coinciden GBIF y WFO; rWCVP sin resultado | F26: Agrimonia striata | G26: Agrimonia striata | H26: Agrimonia striata | I26: - | J26: - | K26: 3 | L26: Agrimonia striata | M26: -
A27: Agrimonia.pilosa | B27: Agrimonia pilosa | D27: Agrimonia pilosa | E27: Coinciden GBIF y WFO; rWCVP sin resultado | F27: Agrimonia pilosa | G27: Agrimonia pilosa | H27: Agrimonia pilosa | I27: - | J27: - | K27: 3 | L27: Agrimonia pilosa | M27: -
A28: Alcea.pallida | B28: Alcea pallida | C28: Alcea biennis | D28: Alcea biennis | E28: Coinciden rWCVP y WFO; GBIF es diferente | F28: Alcea biennis | G28: Alcea biennis | H28: Alcea biennis | I28: - | J28: - | K28: 3 | L28: Alcea biennis | M28: -
A29: Alisma.plantago.aquatica | C29: Alisma plantago-aquatica | D29: Alisma plantago-aquatica | E29: Coinciden rWCVP y WFO; GBIF sin resultado | F29: Alisma plantago-aquatica | G29: Alisma plantago-aquatica | H29: Alisma plantago-aquatica | I29: - | J29: - | K29: 3 | L29: Alisma plantago-aquatica | M29: -
A30: Alium.grayi | C30: Allium macrostemon | D30: Allium macrostemon | E30: Coinciden rWCVP y WFO; GBIF sin resultado | F30: Allium macrostemon | G30: Allium macrostemon | H30: Allium macrostemon | I30: - | J30: - | K30: 3 | L30: Allium macrostemon | M30: -
A31: Alkanna.tinctoria | B31: Alkanna tinctoria | D31: Alkanna tinctoria | E31: Coinciden GBIF y WFO; rWCVP sin resultado | F31: Alkanna tinctoria | G31: Alkanna tinctoria | H31: Alkanna tinctoria | I31: - | J31: - | K31: 3 | L31: Alkanna tinctoria | M31: -
A32: Allium.subhirsutum | B32: Allium subhirsutum | D32: Allium subhirsutum | E32: Coinciden GBIF y WFO; rWCVP sin resultado | F32: Allium subhirsutum | G32: Allium subhirsutum | H32: Allium subhirsutum | I32: - | J32: - | K32: 3 | L32: Allium subhirsutum | M32: -
A33: Allium.ampeloprasum | B33: Allium ampeloprasum | D33: Allium ampeloprasum | E33: Coinciden GBIF y WFO; rWCVP sin resultado | F33: Allium ampeloprasum | G33: Allium ampeloprasum | H33: Allium ampeloprasum | I33: - | J33: - | K33: 3 | L33: Allium ampeloprasum | M33: -
A34: Alstroemeria.aurea | B34: Alstroemeria aurea | D34: Alstroemeria aurea | E34: Coinciden GBIF y WFO; rWCVP sin resultado | F34: Alstroemeria aurea | G34: Alstroemeria aurea | H34: Alstroemeria aurea | I34: - | J34: - | K34: 3 | L34: Alstroemeria aurea | M34: -
A35: Alstromemeria.pallida | C35: Alstroemeria pallida | D35: Alstroemeria pallida | E35: Coinciden rWCVP y WFO; GBIF sin resultado | F35: Alstroemeria pallida | G35: Alstroemeria pallida | H35: Alstroemeria pallida | I35: - | J35: - | K35: 3 | L35: Alstroemeria pallida | M35: -
A36: Alternanthera.ficoidea | B36: Alternanthera ficoidea | D36: Alternanthera ficoidea | E36: Coinciden GBIF y WFO; rWCVP sin resultado | F36: Alternanthera ficoidea | G36: Alternanthera ficoidea | H36: Alternanthera ficoidea | I36: - | J36: - | K36: 3 | L36: Alternanthera ficoidea | M36: -
A37: Alyssum.maritimum | B37: Lobularia maritima | C37: Lobularia maritima | D37: Lobularia maritima subsp. maritima | E37: Coinciden GBIF y rWCVP; WFO es diferente | F37: Lobularia maritima subsp. maritima | G37: Lobularia maritima subsp. maritima | H37: Lobularia maritima subsp. maritima | I37: - | J37: - | K37: 3 | L37: Lobularia maritima subsp. maritima | M37: -
A38: Amelanchier.canadensis | B38: Amelanchier canadensis | D38: Amelanchier canadensis | E38: Coinciden GBIF y WFO; rWCVP sin resultado | F38: Amelanchier canadensis | G38: Amelanchier canadensis | H38: Amelanchier canadensis | I38: - | J38: - | K38: 3 | L38: Amelanchier canadensis | M38: -
A39: Ammannia.coccinea | B39: Ammannia coccinea | D39: Ammannia coccinea | E39: Coinciden GBIF y WFO; rWCVP sin resultado | F39: Ammannia coccinea | G39: Ammannia coccinea | H39: Ammannia coccinea | I39: - | J39: - | K39: 3 | L39: Ammannia coccinea | M39: -
A40: Amorpha.fruticosa | B40: Amorpha fruticosa | D40: Amorpha fruticosa | E40: Coinciden GBIF y WFO; rWCVP sin resultado | F40: Amorpha fruticosa | G40: Amorpha fruticosa | H40: Amorpha fruticosa | I40: - | J40: - | K40: 3 | L40: Amorpha fruticosa | M40: -
...
